<?xml version="1.0" ?>
<!-- =================================================================================== -->
<!-- |    This document was autogenerated by xacro from maxwell.urdf.xacro             | -->
<!-- |    EDITING THIS FILE BY HAND IS NOT RECOMMENDED                                 | -->
<!-- =================================================================================== -->
<robot name="maxwell">
  <!-- deck to arm_link at max height-->
  <!-- deck to top of 80/20 -->
  <!-- The following included files set up definitions of parts of the robot body -->
  <material name="Black">
    <color rgba="0.2 0.2 0.2 1.0"/>
  </material>
  <material name="Orange">
    <color rgba="1.0  0.55 0.0 1.0"/>
  </material>
  <material name="Grey">
    <color rgba="0.7 0.7 0.7 1.0"/>
  </material>
  <material name="Red">
    <color rgba="0.8 0.0 0.0 1.0"/>
  </material>
  <material name="White">
    <color rgba="1.0 1.0 1.0 1.0"/>
  </material>
  <material name="Blue">
    <color rgba="0.0 0.0 0.8 1.0"/>
  </material>
  <!-- Now we can start using the macros included above to define the actual Maxwell -->
  <link name="base_link">
    <visual>
      <origin rpy="0 0 0" xyz="0 0 0.0238"/>
      <geometry>
        <mesh filename="package://maxwell_defs/meshes/base.stl"/>
      </geometry>
      <material name="Black"/>
    </visual>
    <collision>
      <origin rpy="0 0 0" xyz="-0.12065 0 0.0655"/>
      <geometry>
        <box size="0.4064 0.4064 0.131"/>
      </geometry>
    </collision>
  </link>
  <joint name="base_laser_joint" type="fixed">
    <axis xyz="0 1 0"/>
    <origin rpy="0 0 0" xyz="0.0318 0 0.1885"/>
    <parent link="base_link"/>
    <child link="base_laser_link"/>
  </joint>
  <link name="base_laser_link" type="laser">
    <inertial>
      <mass value="0.001"/>
      <origin rpy="0 0 0" xyz="0 0 0"/>
      <inertia ixx="0.0001" ixy="0" ixz="0" iyy="0.000001" iyz="0" izz="0.0001"/>
    </inertial>
    <!--<visual>
        <origin xyz="0 0 -0.022" rpy="0 0 0" />
        <geometry>
          <box size="0.05 0.05 0.071" />
        </geometry>
        <material name="Red" />
      </visual>-->
    <collision>
      <origin rpy="0 0 0" xyz="0 0 -0.022"/>
      <geometry>
        <box size=".05 .05 .071"/>
      </geometry>
    </collision>
  </link>
  <joint name="base_l_wheel_joint" type="continuous">
    <axis xyz="0 0 1"/>
    <limit effort="100" velocity="100"/>
    <safety_controller k_velocity="10"/>
    <origin rpy="1.57 0 0" xyz="0 0.19304 0.06191"/>
    <parent link="base_link"/>
    <child link="base_l_wheel_link"/>
  </joint>
  <link name="base_l_wheel_link">
    <visual>
      <origin rpy="0 0 0" xyz="0 0 0"/>
      <geometry>
        <cylinder length="0.02032" radius="0.06191"/>
      </geometry>
      <material name="Orange"/>
    </visual>
  </link>
  <joint name="base_r_wheel_joint" type="continuous">
    <axis xyz="0 0 1"/>
    <limit effort="100" velocity="100"/>
    <safety_controller k_velocity="10"/>
    <origin rpy="-1.57 0 0" xyz="0 -0.19304 0.06191"/>
    <parent link="base_link"/>
    <child link="base_r_wheel_link"/>
  </joint>
  <link name="base_r_wheel_link">
    <visual>
      <origin rpy="0 0 0" xyz="0 0 0"/>
      <geometry>
        <cylinder length="0.02032" radius="0.06191"/>
      </geometry>
      <material name="Orange"/>
    </visual>
  </link>
  <!-- Add Torso Upright -->
  <joint name="torso_joint" type="fixed">
    <origin rpy="0 0 0" xyz="-0.00635 0 0.7914"/>
    <parent link="base_link"/>
    <child link="torso_link"/>
  </joint>
  <link name="torso_link">
    <visual>
      <origin rpy="0 0 0 " xyz="0 0 -0.0740125"/>
      <geometry>
        <box size="0.0254 0.0254 1.172775"/>
      </geometry>
      <material name="Grey"/>
    </visual>
    <collision>
      <origin rpy="0 0 0 " xyz="0 0 -0.0740125"/>
      <geometry>
        <box size="0.0254 0.0254 1.172775"/>
      </geometry>
    </collision>
  </link>
  <joint name="torso_actuator_joint" type="fixed">
    <origin rpy="0 0 0" xyz="0 0 0"/>
    <parent link="torso_link"/>
    <child link="torso_actuator_link"/>
  </joint>
  <link name="torso_actuator_link">
    <visual>
      <origin rpy="0 0 3.14" xyz="-0.05 -0.0127 -0.560"/>
      <geometry>
        <mesh filename="package://maxwell_defs/meshes/FA-35-TR.stl" scale="0.001 0.001 0.001"/>
      </geometry>
      <material name="Grey"/>
    </visual>
    <collision>
      <origin rpy="0 0 0 " xyz="-0.03 0 -0.245"/>
      <geometry>
        <box size="0.03 0.0254 0.650"/>
      </geometry>
    </collision>
  </link>
  <!-- Live joint between torso and arm -->
  <joint name="arm_lift_joint" type="prismatic">
    <axis xyz="0 0 1"/>
    <limit effort="30" lower="-0.464" upper="0" velocity="0.0508"/>
    <origin rpy="0 0 0" xyz="0 0 0"/>
    <parent link="torso_link"/>
    <child link="arm_lift_link"/>
  </joint>
  <link name="arm_lift_link"/>
  <!-- Arm -->
  <joint name="arm_base_joint" type="fixed">
    <origin rpy="0 0 0" xyz="0.0611 0 0"/>
    <parent link="arm_lift_link"/>
    <child link="arm_link"/>
  </joint>
  <link name="arm_link"/>
  <joint name="arm_left_mount_joint" type="fixed">
    <origin rpy="0 0 0" xyz="-0.0611 0.0254 0"/>
    <parent link="arm_link"/>
    <child link="arm_left_mount_link"/>
  </joint>
  <link name="arm_left_mount_link">
    <visual>
      <origin rpy="1.57 3.14 0" xyz="0 0 -0.034"/>
      <geometry>
        <mesh filename="package://maxwell_defs/meshes/arm_mount.stl" scale="0.001 0.001 0.001"/>
      </geometry>
      <material name="Black"/>
    </visual>
    <collision>
      <origin rpy="0 0 0" xyz="0.03055 -0.00238125 0"/>
      <geometry>
        <box size="0.0865 0.0047625 0.038"/>
      </geometry>
    </collision>
  </link>
  <joint name="arm_right_mount_joint" type="fixed">
    <origin rpy="3.14 0 0" xyz="-0.0611 -0.0254 0"/>
    <parent link="arm_link"/>
    <child link="arm_right_mount_link"/>
  </joint>
  <link name="arm_right_mount_link">
    <visual>
      <origin rpy="1.57 3.14 0" xyz="0 0 -0.034"/>
      <geometry>
        <mesh filename="package://maxwell_defs/meshes/arm_mount.stl" scale="0.001 0.001 0.001"/>
      </geometry>
      <material name="Black"/>
    </visual>
    <collision>
      <origin rpy="0 0 0" xyz="0.03055 -0.00238125 0"/>
      <geometry>
        <box size="0.0865 0.0047625 0.038"/>
      </geometry>
    </collision>
  </link>
  <joint name="arm_shoulder_pan_servo_joint" type="fixed">
    <origin rpy="0 0 0" xyz="0 0 0"/>
    <parent link="arm_link"/>
    <child link="arm_shoulder_pan_servo_link"/>
  </joint>
  <link name="arm_shoulder_pan_servo_link">
    <inertial>
      <mass value="0.00001"/>
      <origin xyz="0 0 0"/>
      <inertia ixx="1.0" ixy="0.0" ixz="0.0" iyy="1.0" iyz="0.0" izz="1.0"/>
    </inertial>
    <visual>
      <origin rpy="0 0 -1.57" xyz=" 0 0 0 "/>
      <geometry>
        <mesh filename="package://maxwell_defs/meshes/rx64.stl" scale="1 1 1"/>
      </geometry>
      <material name="Black"/>
    </visual>
    <collision>
      <origin rpy="0 0 0" xyz="-0.01755 0.0 0"/>
      <geometry>
        <box size="0.0611 0.0420 0.0470"/>
      </geometry>
    </collision>
  </link>
  <joint name="arm_shoulder_pan_joint" type="revolute">
    <origin rpy="0 0 0" xyz="0 0 0.0235"/>
    <axis xyz="0 0 1"/>
    <limit effort="30" lower="-1.57" upper="1.57" velocity="0.524"/>
    <parent link="arm_shoulder_pan_servo_link"/>
    <child link="arm_shoulder_pan_link"/>
  </joint>
  <link name="arm_shoulder_pan_link">
    <inertial>
      <mass value="0.00001"/>
      <origin xyz="0 0 0"/>
      <inertia ixx="1.0" ixy="0.0" ixz="0.0" iyy="1.0" iyz="0.0" izz="1.0"/>
    </inertial>
    <visual>
      <origin rpy="1.57 0 0" xyz=" 0 0 0 "/>
      <geometry>
        <mesh filename="package://maxwell_defs/meshes/rx64-side-bracket.stl" scale="1 1 1"/>
      </geometry>
      <material name="Grey"/>
    </visual>
    <collision>
      <origin rpy="0 0 0" xyz="0.000 0 0.005"/>
      <geometry>
        <box size="0.037 0.037 0.010"/>
      </geometry>
    </collision>
  </link>
  <joint name="arm_shoulder_lift_servo_joint" type="fixed">
    <origin rpy="0 -1.57 0" xyz="0 0 0.0526"/>
    <parent link="arm_shoulder_pan_link"/>
    <child link="arm_shoulder_lift_servo_link"/>
  </joint>
  <link name="arm_shoulder_lift_servo_link">
    <inertial>
      <mass value="0.00001"/>
      <origin xyz="0 0 0"/>
      <inertia ixx="1.0" ixy="0.0" ixz="0.0" iyy="1.0" iyz="0.0" izz="1.0"/>
    </inertial>
    <visual>
      <origin rpy="1.57 1.57 0" xyz=" 0 0 0 "/>
      <geometry>
        <mesh filename="package://maxwell_defs/meshes/rx64.stl" scale="1 1 1"/>
      </geometry>
      <material name="Black"/>
    </visual>
    <collision>
      <origin rpy="0 0 0" xyz="-0.01755 0 0"/>
      <geometry>
        <box size="0.0611 0.0470 0.0420"/>
      </geometry>
    </collision>
  </link>
  <joint name="arm_shoulder_lift_joint" type="revolute">
    <origin rpy="0 1.57 0" xyz="0 0 0"/>
    <axis xyz="0 1 0"/>
    <limit effort="30" lower="-1.77" upper="1.317" velocity="0.524"/>
    <parent link="arm_shoulder_lift_servo_link"/>
    <child link="arm_shoulder_lift_link"/>
  </joint>
  <link name="arm_shoulder_lift_link">
    <inertial>
      <mass value="0.00001"/>
      <origin xyz="0 0 0"/>
      <inertia ixx="1.0" ixy="0.0" ixz="0.0" iyy="1.0" iyz="0.0" izz="1.0"/>
    </inertial>
    <visual>
      <origin rpy="-1.57 0 0" xyz="0 0 0"/>
      <geometry>
        <mesh filename="package://maxwell_defs/meshes/sixdof_bracket2.stl" scale="0.001 0.001 0.001"/>
      </geometry>
      <material name="Black"/>
    </visual>
    <collision>
      <origin rpy="0 0 0" xyz="0.0381 0.0 0.0"/>
      <geometry>
        <box size="0.0762 0.053 0.044"/>
      </geometry>
    </collision>
  </link>
  <joint name="arm_upperarm_roll_servo_joint" type="fixed">
    <origin rpy="1.57 1.57 0" xyz="0.0839978 0 0"/>
    <parent link="arm_shoulder_lift_link"/>
    <child link="arm_upperarm_roll_servo_link"/>
  </joint>
  <link name="arm_upperarm_roll_servo_link">
    <inertial>
      <mass value="0.00001"/>
      <origin xyz="0 0 0"/>
      <inertia ixx="1.0" ixy="0.0" ixz="0.0" iyy="1.0" iyz="0.0" izz="1.0"/>
    </inertial>
    <visual>
      <origin rpy="1.57 1.57 0" xyz=" 0 0 0 "/>
      <geometry>
        <mesh filename="package://maxwell_defs/meshes/rx64.stl" scale="1 1 1"/>
      </geometry>
      <material name="Black"/>
    </visual>
    <collision>
      <origin rpy="0 0 0" xyz="-0.01755 0 0"/>
      <geometry>
        <box size="0.0611 0.0470 0.0420"/>
      </geometry>
    </collision>
  </link>
  <joint name="arm_upperarm_roll_joint" type="revolute">
    <origin rpy="-1.57 0 1.57" xyz="0 0 0"/>
    <axis xyz="1 0 0"/>
    <limit effort="30" lower="-3.14" upper="3.14" velocity="0.524"/>
    <parent link="arm_upperarm_roll_servo_link"/>
    <child link="arm_upperarm_roll_link"/>
  </joint>
  <link name="arm_upperarm_roll_link">
    <inertial>
      <mass value="0.00001"/>
      <origin xyz="0 0 0"/>
      <inertia ixx="1.0" ixy="0.0" ixz="0.0" iyy="1.0" iyz="0.0" izz="1.0"/>
    </inertial>
    <visual>
      <origin rpy="1.57 0 3.14" xyz="0.074295 0 0"/>
      <geometry>
        <mesh filename="package://maxwell_defs/meshes/sixdof_bracket1.stl" scale="0.001 0.001 0.001"/>
      </geometry>
      <material name="Black"/>
    </visual>
    <collision>
      <origin rpy="0 0 0" xyz="0.0381 0.0 0.0"/>
      <geometry>
        <box size="0.0762 0.053 0.044"/>
      </geometry>
    </collision>
  </link>
  <joint name="arm_elbow_flex_joint" type="revolute">
    <origin rpy="0 0 0" xyz="0.074295 0 0"/>
    <axis xyz="0 1 0"/>
    <limit effort="30" lower="-1.57" upper="2.617" velocity="0.524"/>
    <parent link="arm_upperarm_roll_link"/>
    <child link="arm_elbow_flex_link"/>
  </joint>
  <link name="arm_elbow_flex_link">
    <inertial>
      <mass value="0.00001"/>
      <origin xyz="0 0 0"/>
      <inertia ixx="1.0" ixy="0.0" ixz="0.0" iyy="1.0" iyz="0.0" izz="1.0"/>
    </inertial>
    <visual>
      <origin rpy="1.57 -1.57 0" xyz=" 0 0 0 "/>
      <geometry>
        <mesh filename="package://maxwell_defs/meshes/rx64.stl" scale="1 1 1"/>
      </geometry>
      <material name="Black"/>
    </visual>
    <collision>
      <origin rpy="0 0 0" xyz="0.01755 0 0"/>
      <geometry>
        <box size="0.0611 0.0470 0.0420"/>
      </geometry>
    </collision>
  </link>
  <joint name="arm_forearm_fixed_joint" type="fixed">
    <origin rpy="0 0 0" xyz="0 0 0"/>
    <parent link="arm_elbow_flex_link"/>
    <child link="arm_forearm_link"/>
  </joint>
  <link name="arm_forearm_link">
    <inertial>
      <mass value="0.00001"/>
      <origin xyz="0 0 0"/>
      <inertia ixx="1.0" ixy="0.0" ixz="0.0" iyy="1.0" iyz="0.0" izz="1.0"/>
    </inertial>
    <visual>
      <origin rpy="-1.57 0 0" xyz="0 0 0"/>
      <geometry>
        <mesh filename="package://maxwell_defs/meshes/arm_mx64_forearm.stl" scale="1 1 1"/>
      </geometry>
      <material name="Black"/>
    </visual>
    <collision>
      <origin rpy="0 0 0" xyz="0.0625 0.0 0.0"/>
      <geometry>
        <box size="0.03 0.053 0.044"/>
      </geometry>
    </collision>
  </link>
  <joint name="arm_wrist_flex_servo_joint" type="fixed">
    <origin rpy="0 0 0" xyz="0.125 0 0"/>
    <parent link="arm_forearm_link"/>
    <child link="arm_wrist_flex_servo_link"/>
  </joint>
  <link name="arm_wrist_flex_servo_link">
    <inertial>
      <mass value="0.00001"/>
      <origin xyz="0 0 0"/>
      <inertia ixx="1.0" ixy="0.0" ixz="0.0" iyy="1.0" iyz="0.0" izz="1.0"/>
    </inertial>
    <visual>
      <origin rpy="1.57 1.57 0" xyz=" 0 0 0 "/>
      <geometry>
        <mesh filename="package://maxwell_defs/meshes/rx64.stl" scale="1 1 1"/>
      </geometry>
      <material name="Black"/>
    </visual>
    <collision>
      <origin rpy="0 0 0" xyz="-0.01755 0 0"/>
      <geometry>
        <box size="0.0611 0.0470 0.0420"/>
      </geometry>
    </collision>
  </link>
  <joint name="arm_wrist_flex_joint" type="revolute">
    <origin rpy="0 0 0" xyz="0 0 0.0"/>
    <axis xyz="0 1 0"/>
    <limit effort="30" lower="-1.57" upper="1.57" velocity="0.785"/>
    <parent link="arm_wrist_flex_servo_link"/>
    <child link="arm_wrist_flex_link"/>
  </joint>
  <link name="arm_wrist_flex_link">
    <inertial>
      <mass value="0.00001"/>
      <origin xyz="0 0 0"/>
      <inertia ixx="1.0" ixy="0.0" ixz="0.0" iyy="1.0" iyz="0.0" izz="1.0"/>
    </inertial>
    <visual>
      <origin rpy="0 0 -1.57" xyz="0 0 0"/>
      <geometry>
        <mesh filename="package://maxwell_defs/meshes/rx64-hinge-bracket.stl" scale="1 1 1"/>
      </geometry>
      <material name="Grey"/>
    </visual>
    <collision>
      <origin rpy="0 0 0" xyz="0.015 0.0 0.0"/>
      <geometry>
        <box size="0.030 0.056 0.031"/>
      </geometry>
    </collision>
  </link>
  <joint name="arm_wrist_roll_joint" type="revolute">
    <axis xyz="1 0 0"/>
    <limit effort="30" lower="-2.617" upper="2.617" velocity="0.785"/>
    <origin rpy="0 0 0" xyz="0.031 0 0"/>
    <parent link="arm_wrist_flex_link"/>
    <child link="arm_wrist_roll_link"/>
  </joint>
  <link name="arm_wrist_roll_link">
    <inertial>
      <mass value="0.00001"/>
      <origin xyz="0 0 0"/>
      <inertia ixx="1.0" ixy="0.0" ixz="0.0" iyy="1.0" iyz="0.0" izz="1.0"/>
    </inertial>
    <visual>
      <origin rpy="0 0 1.57" xyz="0.01905 0 0"/>
      <geometry>
        <mesh filename="package://maxwell_defs/meshes/ax12.stl" scale="0.001 0.001 0.001"/>
      </geometry>
      <material name="Black"/>
    </visual>
    <collision>
      <origin rpy="0 0 0" xyz="0.02 0.0 -0.0133 "/>
      <geometry>
        <box size="0.040 0.032 0.0501"/>
      </geometry>
    </collision>
  </link>
  <!-- Gripper -->
  <joint name="gripper_F6_1_joint" type="fixed">
    <origin rpy="0 0 0" xyz="0.01905 0.017 -0.014"/>
    <parent link="arm_wrist_roll_link"/>
    <child link="gripper_F6_1_link"/>
  </joint>
  <link name="gripper_F6_1_link">
    <inertial>
      <mass value="0.00001"/>
      <origin xyz="0 0 0"/>
      <inertia ixx="1.0" ixy="0.0" ixz="0.0" iyy="1.0" iyz="0.0" izz="1.0"/>
    </inertial>
    <visual>
      <origin rpy="3.14 0 0" xyz=" 0 0 0 "/>
      <geometry>
        <mesh filename="package://maxwell_defs/meshes/F6.stl" scale="1 1 1"/>
      </geometry>
      <material name="Black"/>
    </visual>
    <collision>
      <origin rpy="0 0 0" xyz="0.001 0.0 0.0"/>
      <geometry>
        <box size="0.04 0.005 0.024"/>
      </geometry>
    </collision>
  </link>
  <joint name="gripper_F6_2_joint" type="fixed">
    <origin rpy="3.14 3.14 0" xyz="0.008 0.004 0"/>
    <parent link="gripper_F6_1_link"/>
    <child link="gripper_F6_2_link"/>
  </joint>
  <link name="gripper_F6_2_link">
    <inertial>
      <mass value="0.00001"/>
      <origin xyz="0 0 0"/>
      <inertia ixx="1.0" ixy="0.0" ixz="0.0" iyy="1.0" iyz="0.0" izz="1.0"/>
    </inertial>
    <visual>
      <origin rpy="3.14 0 0" xyz=" 0 0 0 "/>
      <geometry>
        <mesh filename="package://maxwell_defs/meshes/F6.stl" scale="1 1 1"/>
      </geometry>
      <material name="Black"/>
    </visual>
    <collision>
      <origin rpy="0 0 0" xyz="0.001 0.0 0.0"/>
      <geometry>
        <box size="0.04 0.005 0.024"/>
      </geometry>
    </collision>
  </link>
  <joint name="gripper_F6_3_joint" type="fixed">
    <origin rpy="3.14 0 0" xyz="0.01905 -0.017 -0.014"/>
    <parent link="arm_wrist_roll_link"/>
    <child link="gripper_F6_3_link"/>
  </joint>
  <link name="gripper_F6_3_link">
    <inertial>
      <mass value="0.00001"/>
      <origin xyz="0 0 0"/>
      <inertia ixx="1.0" ixy="0.0" ixz="0.0" iyy="1.0" iyz="0.0" izz="1.0"/>
    </inertial>
    <visual>
      <origin rpy="3.14 0 0" xyz=" 0 0 0 "/>
      <geometry>
        <mesh filename="package://maxwell_defs/meshes/F6.stl" scale="1 1 1"/>
      </geometry>
      <material name="Black"/>
    </visual>
    <collision>
      <origin rpy="0 0 0" xyz="0.001 0.0 0.0"/>
      <geometry>
        <box size="0.04 0.005 0.024"/>
      </geometry>
    </collision>
  </link>
  <joint name="gripper_F6_4_joint" type="fixed">
    <origin rpy="0 0 3.14" xyz="0.008 0.004 0"/>
    <parent link="gripper_F6_3_link"/>
    <child link="gripper_F6_4_link"/>
  </joint>
  <link name="gripper_F6_4_link">
    <inertial>
      <mass value="0.00001"/>
      <origin xyz="0 0 0"/>
      <inertia ixx="1.0" ixy="0.0" ixz="0.0" iyy="1.0" iyz="0.0" izz="1.0"/>
    </inertial>
    <visual>
      <origin rpy="3.14 0 0" xyz=" 0 0 0 "/>
      <geometry>
        <mesh filename="package://maxwell_defs/meshes/F6.stl" scale="1 1 1"/>
      </geometry>
      <material name="Black"/>
    </visual>
    <collision>
      <origin rpy="0 0 0" xyz="0.001 0.0 0.0"/>
      <geometry>
        <box size="0.04 0.005 0.024"/>
      </geometry>
    </collision>
  </link>
  <joint name="left_gripper_mount_joint" type="fixed">
    <origin rpy="1.57 0 1.57" xyz="-0.018 0.005 0"/>
    <parent link="gripper_F6_2_link"/>
    <child link="left_gripper_mount_link"/>
  </joint>
  <link name="left_gripper_mount_link">
    <inertial>
      <mass value="0.00001"/>
      <origin xyz="0 0 0"/>
      <inertia ixx="1.0" ixy="0.0" ixz="0.0" iyy="1.0" iyz="0.0" izz="1.0"/>
    </inertial>
    <visual>
      <origin rpy="0 0 0" xyz=" 0 0 0 "/>
      <geometry>
        <mesh filename="package://maxwell_defs/meshes/F3.stl" scale="0.001 0.001 0.001"/>
      </geometry>
      <material name="Black"/>
    </visual>
    <collision>
      <origin rpy="0 0 0" xyz="0.0 0.0 -0.0045"/>
      <geometry>
        <box size="0.025 0.038 0.009"/>
      </geometry>
    </collision>
  </link>
  <joint name="right_gripper_mount_joint" type="fixed">
    <origin rpy="1.57 0 1.57" xyz="-0.018 0.005 0"/>
    <parent link="gripper_F6_4_link"/>
    <child link="right_gripper_mount_link"/>
  </joint>
  <link name="right_gripper_mount_link">
    <inertial>
      <mass value="0.00001"/>
      <origin xyz="0 0 0"/>
      <inertia ixx="1.0" ixy="0.0" ixz="0.0" iyy="1.0" iyz="0.0" izz="1.0"/>
    </inertial>
    <visual>
      <origin rpy="0 0 0" xyz=" 0 0 0 "/>
      <geometry>
        <mesh filename="package://maxwell_defs/meshes/F3.stl" scale="0.001 0.001 0.001"/>
      </geometry>
      <material name="Black"/>
    </visual>
    <collision>
      <origin rpy="0 0 0" xyz="0.0 0.0 -0.0045"/>
      <geometry>
        <box size="0.025 0.038 0.009"/>
      </geometry>
    </collision>
  </link>
  <joint name="left_gripper_servo_joint" type="fixed">
    <origin rpy="-1.57 1.57 0" xyz="0 0 -0.042"/>
    <parent link="left_gripper_mount_link"/>
    <child link="left_gripper_servo_link"/>
  </joint>
  <link name="left_gripper_servo_link">
    <inertial>
      <mass value="0.00001"/>
      <origin xyz="0 0 0"/>
      <inertia ixx="1.0" ixy="0.0" ixz="0.0" iyy="1.0" iyz="0.0" izz="1.0"/>
    </inertial>
    <visual>
      <origin rpy="1.57 0 1.57" xyz=" 0 0 0 "/>
      <geometry>
        <mesh filename="package://maxwell_defs/meshes/ax12.stl" scale="0.001 0.001 0.001"/>
      </geometry>
      <material name="Black"/>
    </visual>
    <collision>
      <origin rpy="0 0 0" xyz="-0.01345 0.0 0.0"/>
      <geometry>
        <box size="0.0501 0.032 0.040"/>
      </geometry>
    </collision>
  </link>
  <joint name="right_gripper_servo_joint" type="fixed">
    <origin rpy="1.57 1.57 0" xyz="0 0 -0.042"/>
    <parent link="right_gripper_mount_link"/>
    <child link="right_gripper_servo_link"/>
  </joint>
  <link name="right_gripper_servo_link">
    <inertial>
      <mass value="0.00001"/>
      <origin xyz="0 0 0"/>
      <inertia ixx="1.0" ixy="0.0" ixz="0.0" iyy="1.0" iyz="0.0" izz="1.0"/>
    </inertial>
    <visual>
      <origin rpy="1.57 0 1.57" xyz=" 0 0 0 "/>
      <geometry>
        <mesh filename="package://maxwell_defs/meshes/ax12.stl" scale="0.001 0.001 0.001"/>
      </geometry>
      <material name="Black"/>
    </visual>
    <collision>
      <origin rpy="0 0 0" xyz="-0.01345 0.0 0.0"/>
      <geometry>
        <box size="0.0501 0.032 0.040"/>
      </geometry>
    </collision>
  </link>
  <joint name="l_gripper_joint" type="revolute">
    <origin rpy="3.14 0 1.57" xyz="0 0 0"/>
    <axis xyz="0 0 1"/>
    <limit effort="30" lower="-1.57" upper="1.57" velocity="0.5"/>
    <parent link="left_gripper_servo_link"/>
    <child link="l_gripper_link"/>
  </joint>
  <link name="l_gripper_link">
    <inertial>
      <mass value="0.00001"/>
      <origin xyz="0 0 0"/>
      <inertia ixx="1.0" ixy="0.0" ixz="0.0" iyy="1.0" iyz="0.0" izz="1.0"/>
    </inertial>
    <visual>
      <origin rpy="3.14 0 0" xyz=" 0 0 0 "/>
      <geometry>
        <mesh filename="package://maxwell_defs/meshes/F1.stl" scale="1 1 1"/>
      </geometry>
      <material name="Orange"/>
    </visual>
    <collision>
      <origin rpy="0 0 .8" xyz="0.01 0.008 0.0"/>
      <geometry>
        <box size="0.04 0.028 0.046"/>
      </geometry>
    </collision>
  </link>
  <joint name="r_gripper_joint" type="revolute">
    <origin rpy="0 0 -1.57" xyz="0 0 0"/>
    <axis xyz="0 0 1"/>
    <limit effort="30" lower="-1.57" upper="1.57" velocity="0.5"/>
    <parent link="right_gripper_servo_link"/>
    <child link="r_gripper_link"/>
  </joint>
  <link name="r_gripper_link">
    <inertial>
      <mass value="0.00001"/>
      <origin xyz="0 0 0"/>
      <inertia ixx="1.0" ixy="0.0" ixz="0.0" iyy="1.0" iyz="0.0" izz="1.0"/>
    </inertial>
    <visual>
      <origin rpy="3.14 0 0" xyz=" 0 0 0 "/>
      <geometry>
        <mesh filename="package://maxwell_defs/meshes/F1.stl" scale="1 1 1"/>
      </geometry>
      <material name="Orange"/>
    </visual>
    <collision>
      <origin rpy="0 0 .8" xyz="0.01 0.008 0.0"/>
      <geometry>
        <box size="0.04 0.028 0.046"/>
      </geometry>
    </collision>
  </link>
  <joint name="left_gripper_F9_joint" type="fixed">
    <origin rpy="0 3.14 0" xyz="0.0155 0.038 0"/>
    <parent link="l_gripper_link"/>
    <child link="left_gripper_F9_link"/>
  </joint>
  <link name="left_gripper_F9_link">
    <inertial>
      <mass value="0.00001"/>
      <origin xyz="0 0 0"/>
      <inertia ixx="1.0" ixy="0.0" ixz="0.0" iyy="1.0" iyz="0.0" izz="1.0"/>
    </inertial>
    <visual>
      <origin rpy="0 0 0" xyz="0 0 0"/>
      <geometry>
        <mesh filename="package://maxwell_defs/meshes/F9.stl" scale="1 1 1"/>
      </geometry>
      <material name="Black"/>
    </visual>
    <collision>
      <origin rpy="0 0 0" xyz="-0.008 0.0 0.0"/>
      <geometry>
        <box size="0.008 0.03 0.024"/>
      </geometry>
    </collision>
  </link>
  <joint name="right_gripper_F9_joint" type="fixed">
    <origin rpy="0 3.14 0" xyz="0.0155 0.038 0"/>
    <parent link="r_gripper_link"/>
    <child link="right_gripper_F9_link"/>
  </joint>
  <link name="right_gripper_F9_link">
    <inertial>
      <mass value="0.00001"/>
      <origin xyz="0 0 0"/>
      <inertia ixx="1.0" ixy="0.0" ixz="0.0" iyy="1.0" iyz="0.0" izz="1.0"/>
    </inertial>
    <visual>
      <origin rpy="0 0 0" xyz="0 0 0"/>
      <geometry>
        <mesh filename="package://maxwell_defs/meshes/F9.stl" scale="1 1 1"/>
      </geometry>
      <material name="Black"/>
    </visual>
    <collision>
      <origin rpy="0 0 0" xyz="-0.008 0.0 0.0"/>
      <geometry>
        <box size="0.008 0.03 0.024"/>
      </geometry>
    </collision>
  </link>
  <joint name="left_gripper_finger_joint" type="fixed">
    <origin rpy="0 0 0" xyz="0 -0.013 0 "/>
    <parent link="left_gripper_F9_link"/>
    <child link="left_gripper_finger_link"/>
  </joint>
  <link name="left_gripper_finger_link">
    <inertial>
      <mass value="0.00001"/>
      <origin xyz="0 0 0"/>
      <inertia ixx="1.0" ixy="0.0" ixz="0.0" iyy="1.0" iyz="0.0" izz="1.0"/>
    </inertial>
    <visual>
      <origin rpy="0 0 0" xyz="0 0 0"/>
      <geometry>
        <mesh filename="package://maxwell_defs/meshes/F11.stl" scale="1 1 1"/>
      </geometry>
      <material name="Grey"/>
    </visual>
    <collision>
      <origin rpy="0 0 0" xyz="-0.008 0.025 0.0"/>
      <geometry>
        <box size="0.009 0.06 0.028"/>
      </geometry>
    </collision>
  </link>
  <joint name="right_gripper_finger_joint" type="fixed">
    <origin rpy="0 0 0" xyz="0 -0.013 0"/>
    <parent link="right_gripper_F9_link"/>
    <child link="right_gripper_finger_link"/>
  </joint>
  <link name="right_gripper_finger_link">
    <inertial>
      <mass value="0.00001"/>
      <origin xyz="0 0 0"/>
      <inertia ixx="1.0" ixy="0.0" ixz="0.0" iyy="1.0" iyz="0.0" izz="1.0"/>
    </inertial>
    <visual>
      <origin rpy="0 0 0" xyz="0 0 0"/>
      <geometry>
        <mesh filename="package://maxwell_defs/meshes/F11.stl" scale="1 1 1"/>
      </geometry>
      <material name="Grey"/>
    </visual>
    <collision>
      <origin rpy="0 0 0" xyz="-0.008 0.025 0.0"/>
      <geometry>
        <box size="0.009 0.06 0.028"/>
      </geometry>
    </collision>
  </link>
  <joint name="gripper_joint" type="fixed">
    <axis xyz="0 0 1"/>
    <origin rpy="0 0 0" xyz="0.15 0 -0.015"/>
    <parent link="arm_wrist_roll_link"/>
    <child link="gripper_link"/>
  </joint>
  <link name="gripper_link">
    <visual>
      <origin rpy="0 0 0" xyz="0.0 0.0 0"/>
      <geometry>
        <sphere radius="0.0005"/>
      </geometry>
    </visual>
  </link>
  <!-- Head -->
  <joint name="head_joint" type="fixed">
    <origin rpy="0 0 0" xyz="0 0 0.512375"/>
    <parent link="torso_link"/>
    <child link="head_link"/>
  </joint>
  <link name="head_link"/>
  <joint name="head_left_mount_joint" type="fixed">
    <origin rpy="0 0 0" xyz="0 0.01905 0"/>
    <parent link="head_link"/>
    <child link="head_left_mount_link"/>
  </joint>
  <link name="head_left_mount_link">
    <visual>
      <origin rpy="-1.57 3.14 0" xyz="0 0 0"/>
      <geometry>
        <mesh filename="package://maxwell_defs/meshes/head_mount.stl" scale="1 1 1"/>
      </geometry>
      <material name="Black"/>
    </visual>
    <collision>
      <origin rpy="0 1.57 0" xyz="0 0 0"/>
      <geometry>
        <box size="0.0865 0.0047625 0.038"/>
      </geometry>
    </collision>
  </link>
  <joint name="head_right_mount_joint" type="fixed">
    <origin rpy="0 0 0" xyz="0 -0.022225 0"/>
    <parent link="head_link"/>
    <child link="head_right_mount_link"/>
  </joint>
  <link name="head_right_mount_link">
    <visual>
      <origin rpy="-1.57 3.14 0" xyz="0 0 0"/>
      <geometry>
        <mesh filename="package://maxwell_defs/meshes/head_mount.stl" scale="1 1 1"/>
      </geometry>
      <material name="Black"/>
    </visual>
    <collision>
      <origin rpy="0 1.57 0" xyz="0 0 0"/>
      <geometry>
        <box size="0.0865 0.0047625 0.038"/>
      </geometry>
    </collision>
  </link>
  <joint name="head_pan_servo_joint" type="fixed">
    <origin rpy="0 0 0" xyz="0.010 0 0.0254"/>
    <parent link="head_link"/>
    <child link="head_pan_servo_link"/>
  </joint>
  <link name="head_pan_servo_link">
    <inertial>
      <mass value="0.00001"/>
      <origin xyz="0 0 0"/>
      <inertia ixx="1.0" ixy="0.0" ixz="0.0" iyy="1.0" iyz="0.0" izz="1.0"/>
    </inertial>
    <visual>
      <origin rpy="1.57 0 1.57" xyz=" 0 0 0 "/>
      <geometry>
        <mesh filename="package://maxwell_defs/meshes/ax12.stl" scale="0.001 0.001 0.001"/>
      </geometry>
      <material name="Black"/>
    </visual>
    <collision>
      <origin rpy="0 0 0" xyz="-0.01345 0.0 0.0"/>
      <geometry>
        <box size="0.0501 0.032 0.040"/>
      </geometry>
    </collision>
  </link>
  <joint name="head_pan_joint" type="revolute">
    <origin rpy="0 0 0" xyz="0 0 0.019"/>
    <axis xyz="0 0 1"/>
    <limit effort="30" lower="-2.617" upper="2.617" velocity="1.0"/>
    <parent link="head_pan_servo_link"/>
    <child link="head_pan_link"/>
  </joint>
  <link name="head_pan_link">
    <inertial>
      <mass value="0.00001"/>
      <origin xyz="0 0 0"/>
      <inertia ixx="1.0" ixy="0.0" ixz="0.0" iyy="1.0" iyz="0.0" izz="1.0"/>
    </inertial>
    <visual>
      <origin rpy="3.14 0 0" xyz=" 0 0 0 "/>
      <geometry>
        <mesh filename="package://maxwell_defs/meshes/F3.stl" scale="0.001 0.001 0.001"/>
      </geometry>
      <material name="Orange"/>
    </visual>
    <collision>
      <origin rpy="0 0 0" xyz="0.0 0.0 0.0045"/>
      <geometry>
        <box size="0.025 0.038 0.009"/>
      </geometry>
    </collision>
  </link>
  <joint name="head_tilt_left_side_joint" type="fixed">
    <origin rpy="1.57 0 0" xyz="-0.015 -0.019 0"/>
    <parent link="head_pan_servo_link"/>
    <child link="head_tilt_left_side_link"/>
  </joint>
  <link name="head_tilt_left_side_link">
    <inertial>
      <mass value="0.00001"/>
      <origin xyz="0 0 0"/>
      <inertia ixx="1.0" ixy="0.0" ixz="0.0" iyy="1.0" iyz="0.0" izz="1.0"/>
    </inertial>
    <visual>
      <origin rpy="0 0 0" xyz=" 0 0 0 "/>
      <geometry>
        <mesh filename="package://maxwell_defs/meshes/F3.stl" scale="0.001 0.001 0.001"/>
      </geometry>
      <material name="Black"/>
    </visual>
    <collision>
      <origin rpy="0 0 0" xyz="0.0 0.0 -0.0045"/>
      <geometry>
        <box size="0.025 0.038 0.009"/>
      </geometry>
    </collision>
  </link>
  <joint name="head_tilt_right_side_joint" type="fixed">
    <origin rpy="-1.57 0 0" xyz="-0.015 0.019 0"/>
    <parent link="head_pan_servo_link"/>
    <child link="head_tilt_right_side_link"/>
  </joint>
  <link name="head_tilt_right_side_link">
    <inertial>
      <mass value="0.00001"/>
      <origin xyz="0 0 0"/>
      <inertia ixx="1.0" ixy="0.0" ixz="0.0" iyy="1.0" iyz="0.0" izz="1.0"/>
    </inertial>
    <visual>
      <origin rpy="0 0 0" xyz=" 0 0 0 "/>
      <geometry>
        <mesh filename="package://maxwell_defs/meshes/F3.stl" scale="0.001 0.001 0.001"/>
      </geometry>
      <material name="Black"/>
    </visual>
    <collision>
      <origin rpy="0 0 0" xyz="0.0 0.0 -0.0045"/>
      <geometry>
        <box size="0.025 0.038 0.009"/>
      </geometry>
    </collision>
  </link>
  <joint name="head_tilt_servo_joint" type="fixed">
    <origin rpy="0 0 0" xyz="0 0 0.0415"/>
    <parent link="head_pan_link"/>
    <child link="head_tilt_servo_link"/>
  </joint>
  <link name="head_tilt_servo_link">
    <inertial>
      <mass value="0.00001"/>
      <origin xyz="0 0 0"/>
      <inertia ixx="1.0" ixy="0.0" ixz="0.0" iyy="1.0" iyz="0.0" izz="1.0"/>
    </inertial>
    <visual>
      <origin rpy="0 0 0" xyz=" 0 0 0 "/>
      <geometry>
        <mesh filename="package://maxwell_defs/meshes/ax12.stl" scale="0.001 0.001 0.001"/>
      </geometry>
      <material name="Black"/>
    </visual>
    <collision>
      <origin rpy="0 0 0" xyz="0.0 0.0 -0.01345"/>
      <geometry>
        <box size="0.032 0.040 0.0501"/>
      </geometry>
    </collision>
  </link>
  <joint name="head_tilt_joint" type="revolute">
    <origin rpy="0 0 0" xyz="0 0 0"/>
    <axis xyz="0 1 0"/>
    <limit effort="30" lower="-1.57" upper="1.57" velocity="1.0"/>
    <parent link="head_tilt_servo_link"/>
    <child link="head_tilt_link"/>
  </joint>
  <link name="head_tilt_link">
    <inertial>
      <mass value="0.00001"/>
      <origin xyz="0 0 0"/>
      <inertia ixx="1.0" ixy="0.0" ixz="0.0" iyy="1.0" iyz="0.0" izz="1.0"/>
    </inertial>
    <visual>
      <origin rpy="0 0 0" xyz=" 0 0 0 "/>
      <geometry>
        <mesh filename="package://maxwell_defs/meshes/F2.stl" scale="0.001 0.001 0.001"/>
      </geometry>
      <material name="Orange"/>
    </visual>
    <collision>
      <origin rpy="0 0 0" xyz="0.0 0.0 0.00775"/>
      <geometry>
        <box size="0.025 0.0485 0.0375"/>
      </geometry>
    </collision>
  </link>
  <joint name="head_camera_frame_joint" type="fixed">
    <origin rpy="0 0 0" xyz="0 0 0.026"/>
    <parent link="head_tilt_link"/>
    <child link="head_camera_frame"/>
  </joint>
  <link name="head_camera_frame">
    <visual>
      <origin rpy="0 0 -1.57" xyz="0 0 0"/>
      <geometry>
        <mesh filename="package://maxwell_defs/meshes/xtion.stl" scale="0.001 0.001 0.001"/>
      </geometry>
      <material name="Black"/>
    </visual>
    <collision>
      <origin rpy="0 0 0" xyz="0 0 0.032075"/>
      <geometry>
        <box size="0.0381 0.1793875 0.0254"/>
      </geometry>
    </collision>
  </link>
  <joint name="head_camera_ir_joint" type="fixed">
    <origin rpy="0 0 0" xyz="0.01905 -0.0269875 0.032075"/>
    <parent link="head_camera_frame"/>
    <child link="head_camera_ir_link"/>
  </joint>
  <link name="head_camera_ir_link">
    <visual>
      <origin rpy="0 0 0" xyz="0.0 0.0 0"/>
      <geometry>
        <sphere radius="0.0005"/>
      </geometry>
    </visual>
  </link>
  <joint name="head_camera_ir_optical_frame_joint" type="fixed">
    <origin rpy="-1.57 0.0 -1.57" xyz="0 0 0"/>
    <parent link="head_camera_ir_link"/>
    <child link="head_camera_ir_optical_frame"/>
  </joint>
  <link name="head_camera_ir_optical_frame"/>
  <joint name="head_camera_rgb_joint" type="fixed">
    <origin rpy="0 -0.08 0" xyz="0 0.0552875 0"/>
    <parent link="head_camera_ir_link"/>
    <child link="head_camera_rgb_link"/>
  </joint>
  <link name="head_camera_rgb_link">
    <visual>
      <origin rpy="0 0 0" xyz="0.0 0.0 0"/>
      <geometry>
        <sphere radius="0.0005"/>
      </geometry>
    </visual>
  </link>
  <joint name="head_camera_rgb_optical_frame_joint" type="fixed">
    <origin rpy="-1.57 0.0 -1.57" xyz="0 0 0"/>
    <parent link="head_camera_rgb_link"/>
    <child link="head_camera_rgb_optical_frame"/>
  </joint>
  <link name="head_camera_rgb_optical_frame"/>
</robot>

